I'm sorry, but an uncaught exception occurred.

While running game code:
  File "game/script.rpy", line 132, in script
    show guild pos (0, 0)
Exception: Image 'guild' does not accept attributes 'pos (0, 0)'.

-- Full Traceback ------------------------------------------------------------

Full traceback:
  File "game/script.rpy", line 132, in script
    show guild pos (0, 0)
  File "D:\RE\Descargas\renpy-8.3.7-sdk\renpy\ast.py", line 1124, in execute
    show_imspec(self.imspec, atl=getattr(self, "atl", None))
  File "D:\RE\Descargas\renpy-8.3.7-sdk\renpy\ast.py", line 1087, in show_imspec
    renpy.config.show(name,
  File "D:\RE\Descargas\renpy-8.3.7-sdk\renpy\exports\displayexports.py", line 477, in show
    if not base.find_target() and renpy.config.missing_show:
  File "D:\RE\Descargas\renpy-8.3.7-sdk\renpy\display\image.py", line 421, in find_target
    self.target = target._duplicate(a)
  File "D:\RE\Descargas\renpy-8.3.7-sdk\renpy\display\displayable.py", line 249, in _duplicate
    args.extraneous()
  File "D:\RE\Descargas\renpy-8.3.7-sdk\renpy\display\displayable.py", line 109, in extraneous
    raise Exception("Image '{}' does not accept attributes '{}'.".format(
Exception: Image 'guild' does not accept attributes 'pos (0, 0)'.

Windows-10-10.0.19041 AMD64
Ren'Py 8.3.7.25031702
JONT Port by Rec3ks ver. 0.0.16
Tue May 13 01:23:54 2025
